<?xml version="1.0"?>
<robot xmlns:xacro="http://www.ros.org/wiki/xacro">

  <!-- caster wheel -->
    <joint name="caster_joint" type="fixed">
        <parent link="base_link"/>
        <child link="caster"/>
        <origin xyz="-0.15678 0 0"/>   
    </joint>

    <link name="caster">
        <visual>
            <geometry>
                <sphere radius="0.037"/>
            </geometry>
            <material name="white"/>
        </visual>

        <collision>
            <geometry>
                <sphere radius="0.037"/>
            </geometry>
        </collision>
    </link>


    <!-- left wheel link -->
    <joint name="left_wheel_joint" type="continuous">
        <parent link="base_link"/>
        <child link="left_wheel"/>
        <origin xyz="0 0.128 0.028" rpy="-${pi/2} 0 0"/>
        <axis xyz="0 0 1"/>   
    </joint>

     <link name="left_wheel">
        <visual>
            <geometry>
                <cylinder radius="0.065" length="0.02"/>
            </geometry>
            <material name="black"/>
        </visual>

        <collision>
            <geometry>
                <cylinder radius="0.065" length="0.02"/>
            </geometry>
        </collision>
    </link>


    <!-- right wheel link -->
    <joint name="right_wheel_joint" type="continuous">
        <parent link="base_link"/>
        <child link="right_wheel"/>
        <origin xyz="0 -0.128 0.028" rpy="${pi/2} 0 0"/>
        <axis xyz="0 0 -1"/>   
    </joint>

     <link name="right_wheel">
        <visual>
            <geometry>
                <cylinder radius="0.065" length="0.02"/>
            </geometry>
            <material name="black"/>
        </visual>

        <collision>
            <geometry>
                <cylinder radius="0.065" length="0.02"/>
            </geometry>
        </collision>
    </link>

</robot>